Workbook

Sheet Cover
B2: GridMats® Solar Walkway
B3: Pilot and rollout cost-benefit model
B5: Prepared for | C5: =ClientEntity -> [Client legal entity]
B6: Site | C6: =SiteName&", "&SiteCity -> [Campus or site name], [City, State]
B7: Date / prepared by | C7: =PropDate&" · "&PreparedBy -> [Month Year] · GridMats (GroundReality Enterprises Pvt. Ltd.)
B8: Scenario | C8: =Scenario -> Base
B10: Headline results
B11: Pilot
B12: Pilot area (m²) / rated power (kWp) | C12: =TEXT(PilotArea,"0")&" m² · "&TEXT(PilotKWp,"0.0")&" kWp" -> 20 m² · 3.2 kWp
B13: Generation in year 1 (kWh) | C13: =PilotKWh1 -> 4304.8107
B14: Client pays, ex-GST (₹) | C14: =PilotPays -> 182498
B15: GridMats contribution (₹) | C15: =PilotContrib -> 345000
B16: Pilot payback on the client's outlay (years) | C16: =PE_Payback -> 5.0557769
B17: Campus rollout
B18: Rollout area (m²) | C18: =CampusArea -> 1000
B19: Installed cost (₹/sq ft) | C19: =RO_CostSqft -> 1080.7328
B20: Simple payback (years) | C20: =RO_Payback -> 5.6296845
B21: IRR over 20 years | C21: =RO_IRR -> 0.18191176
B22: Comparison (same footprint)
B23: Payback: walkway / rooftop / paver walkway + rooftop (years) | C23: =TEXT(CMP_Payback_W,"0.0")&" / "&TEXT(CMP_Payback_Roof,"0.0")&" / "&TEXT(CMP_Payback_ConvRoof,"0.0") -> 6.6 / 3.0 / 3.5
B25: How to use this template
B26: 1. For a new client, change the yellow cells on 'Client' (or build from clients/<id>.json with build/build.sh). Nothing else needs editing.
B27: 2. GridMats product prices and assumptions sit on 'Product & Costs'; change them only when the price list or design basis changes.
B28: 3. Pick the sunshine profile on 'Client'; replace the city row on 'Irradiance' with site data after the site assessment.
B29: 4. Blue = input · yellow fill = key assumption to confirm · black = formula · green = link to another sheet.
B30: 5. All money in ₹, ex-GST unless stated. The Solar Walkway is pre-commercial: yield, life and upkeep are estimates the pilot measures.

Sheet Client
A1: Client and site: [Client]
A2: Everything that changes from one client to the next is on this sheet. Yellow cells are the ones to confirm first.
A4: Item | B4: Unit | C4: Value used | D4: Conservative | E4: Base | F4: Optimistic | G4: Source / note
A5: Scenario used across the model | C5: Base | D5: Conservative | E5: Base | F5: Optimistic | G5: Switches performance ratio and degradation on 'Product & Costs'.
A6: Scenario index | C6: =MATCH(C5,D5:F5,0) -> 2
A8: 1. Client and site
A9: Client (short name used on slides) | B9: text | C9: [Client] | G9: Shown on the cover and slides.
A10: Client legal entity | B10: text | C10: [Client legal entity] | G10: Use the entity that will issue the PO.
A11: Campus / site | B11: text | C11: [Campus or site name] | G11: Confirm at the site walk.
A12: City, state | B12: text | C12: [City, State]
A13: Sunshine profile (city) | B13: choice | C13: Bengaluru | G13: Monthly sunshine from the 'Irradiance' sheet. Replace with site data after the site assessment.
A14: Electricity supplier | B14: text | C14: [Electricity supplier]
A15: Tariff category | B15: text | C15: [Tariff category, from the site's electricity bill] | G15: Confirm from the campus electricity bill.
A17: 2. Power price and site losses
A18: Grid power cost avoided, year 1 (landed) | B18: ₹ / kWh | C18: 9 | G18: Placeholder: replace with the landed ₹/kWh from the site's electricity bill.
A19: Power tariff escalation | B19: % / yr | C19: 0.03 | G19: Assumption.
A20: Site shading loss (trees, buildings) | B20: % | C20: 0.05 | G20: Assumption until the site assessment measures it.
A22: 3. Pilot and rollout size
A23: Build type | B23: choice | C23: New walkway | G23: 'New walkway' builds the base and credits the paver walkway it replaces; 'Overlay on existing paving' levels the existing path and adds edge ramps.
A24: Pilot walkway length | B24: m | C24: 10 | G24: Pilots are 20-25 m².
A25: Pilot walkway width | B25: m | C25: 2
A26: Pilot area | B26: m² | C26: =PilotL*PilotW -> 20 | G26: Length × width.
A27: Phase 2 area (after the pilot) | B27: m² | C27: 200 | G27: Illustrative.
A28: Campus rollout area | B28: m² | C28: 1000 | G28: Used on 'Rollout Economics' and 'Comparison'.
A29: Portfolio area | B29: m² | C29: 5000 | G29: [Other sites] (illustrative)
A31: 4. Commercial and finance
A32: GridMats co-funding of the pilot PV layer | B32: % | C32: 0.5 | G32: Pilot offer. Needs MD approval per pilot.
A33: Discount rate | B33: % | C33: 0.1 | G33: Client hurdle rate; 10% if not given.
A34: Client income-tax rate | B34: % | C34: 0.2517 | G34: Section 115BAA rate; used for the after-tax view.
A35: Evaluation period before the rollout decision | B35: months | C35: 3 | G35: Earlier Jio proposal letter: 3-month pilot evaluation.
A36: Monitoring period | B36: months | C36: 12 | G36: Covers one monsoon.
A37: Proposal date | B37: text | C37: [Month Year]
A38: Prepared by | B38: text | C38: GridMats (GroundReality Enterprises Pvt. Ltd.)

Sheet Product & Costs
A1: GridMats Solar Walkway: product and cost assumptions
A2: Standard GridMats inputs, the same for every client. ₹ shown per sq ft first, then per m², ex-GST.
A4: Assumption | B4: Unit | C4: Value used | D4: Conservative | E4: Base | F4: Optimistic | G4: Source / note
A5: 1. Product: module technology and rated power
A6: Cell technology of the walkable module | B6: choice | C6: TOPCon (n-type) | G6: Pick from the 'Module Tech' library. Drives temperature loss and degradation; confirm with the module supplier's datasheet.
A7: Rated-power basis | B7: choice | C7: Design basis (40 W per module) | G7: Design basis = the MD-approved 40 W per module. 'Technology-derived' rates the module from its cell technology (upgrade path, to be validated).
A8: Design-basis module rated power | B8: Wp | C8: 40 | G8: GridMats Solar Walkway flier (6 Oct 2026) and Client/Partner Deck v2.
A9: Modules per m² of walkway (one on each 500 × 500 mm grid) | B9: nos / m² | C9: 4 | G9: Flier (6 Oct 2026): 4 grids per m².
A10: Module length | B10: mm | C10: 550 | G10: Client/Partner Deck v2.
A11: Module width | B11: mm | C11: 400 | G11: Client/Partner Deck v2.
A12: Module area | B12: m² | C12: =ModL*ModWd/1000000 -> 0.22 | G12: Length × width.
A13: Cell efficiency, mass production (selected technology) | B13: % | C13: =INDEX('Module Tech'!$C$6:$C$8,MATCH(TechSel,'Module Tech'!$B$6:$B$8,0)) -> 0.258 | G13: From 'Module Tech'.
A14: Standard module efficiency (selected technology) | B14: % | C14: =INDEX('Module Tech'!$E$6:$E$8,MATCH(TechSel,'Module Tech'!$B$6:$B$8,0)) -> 0.235 | G14: From 'Module Tech'.
A15: Temperature coefficient of power | B15: % / °C | C15: =INDEX('Module Tech'!$F$6:$F$8,MATCH(TechSel,'Module Tech'!$B$6:$B$8,0)) -> -0.0029 | G15: From 'Module Tech'.
A16: First-year degradation | B16: % | C16: =INDEX('Module Tech'!$G$6:$G$8,MATCH(TechSel,'Module Tech'!$B$6:$B$8,0)) -> 0.01 | G16: From 'Module Tech'.
A17: Annual degradation after year 1 | B17: % / yr | C17: =INDEX('Module Tech'!$H$6:$H$8,MATCH(TechSel,'Module Tech'!$B$6:$B$8,0)) -> 0.004 | G17: From 'Module Tech'.
A18: Walk-on build loss vs a standard module (thick textured glass, lower cell packing) | B18: % | C18: 0.15 | G18: Assumption for the technology-derived rating. The 40 W design basis implies about 23% on a 23.5% TOPCon module.
A19: Technology-derived module rating | B19: Wp | C19: =ModArea*TechModEff*(1-WalkPackLoss)*1000 -> 43.945 | G19: Module area × efficiency × (1 − walk-on loss).
A20: Module rated power used | B20: Wp | C20: =IF(PowerBasis="Technology-derived",ModWTech,ModWBasis) -> 40 | G20: Per the rated-power basis above.
A21: Rated power of the walkway | B21: Wp / m² | C21: =ModW*ModPerM2 -> 160 | G21: About 160 W/m² on the design basis (flier, 6 Oct 2026).
A22: Walkway module efficiency (check) | B22: % | C22: =ModW/(ModArea*1000) -> 0.18181818 | G22: Wp ÷ (module area × 1,000 W/m²).
A23: Surface efficiency of the walkway | B23: % | C23: =PowerDens/1000 -> 0.16 | G23: Flier: 15-16% surface efficiency.
A25: 2. Performance: loss stack for flat, walk-on modules
A26: Irradiance-weighted cell temperature on the walkway | B26: °C | C26: =INDEX(D26:F26,ScnIdx) -> 52 | D26: 60 | E26: 52 | F26: 45 | G26: Assumption. Pavement-integrated PV runs about 20 °C hotter than open-rack; GridMats' 50 mm gaps ventilate the modules.
A27: Temperature loss | B27: % | C27: =-TechTempCoef*(Tcell-25) -> 0.0783 | G27: −temperature coefficient × (cell temperature − 25 °C).
A28: Soiling (flat surface, foot traffic; monthly cleaning) | B28: % | C28: =INDEX(D28:F28,ScnIdx) -> 0.08 | D28: 0.15 | E28: 0.08 | F28: 0.04 | G28: Horizontal modules soil about twice as fast as tilted ones; annual losses of 5-18% reported without frequent cleaning.
A29: Shading by people walking on it | B29: % | C29: =INDEX(D29:F29,ScnIdx) -> 0.04 | D29: 0.08 | E29: 0.04 | F29: 0.02 | G29: Assumption; depends on footfall at the chosen walkway.
A30: Reflection and angle losses (flat, textured glass) | B30: % | C30: =INDEX(D30:F30,ScnIdx) -> 0.03 | D30: 0.05 | E30: 0.03 | F30: 0.02 | G30: Assumption.
A31: Mismatch and DC wiring | B31: % | C31: =INDEX(D31:F31,ScnIdx) -> 0.03 | D31: 0.04 | E31: 0.03 | F31: 0.02 | G31: Assumption.
A32: Inverter | B32: % | C32: =INDEX(D32:F32,ScnIdx) -> 0.035 | D32: 0.04 | E32: 0.035 | F32: 0.025 | G32: Assumption.
A33: Availability | B33: % | C33: =INDEX(D33:F33,ScnIdx) -> 0.01 | D33: 0.03 | E33: 0.01 | F33: 0.005 | G33: Assumption.
A34: Performance ratio (product of the losses above) | B34: % | C34: =(1-LossTemp)*(1-LossSoil)*(1-LossFoot)*(1-LossRefl)*(1-LossMism)*(1-LossInv)*(1-LossAvail) -> 0.73173634 | G34: Earlier ROI model used a flat 78% (tilted C&I). Field results for road- and walk-integrated PV have been about half of rooftop yield per m²; the conservative case reflects that.
A35: Extra degradation from walk-on use | B35: % / yr | C35: =INDEX(D35:F35,ScnIdx) -> 0.002 | D35: 0.004 | E35: 0.002 | F35: 0.001 | G35: Assumption.
A36: First-year degradation used | B36: % | C36: =TechDeg1 -> 0.01 | G36: Selected technology.
A37: Annual degradation used (technology + walk-on wear) | B37: % / yr | C37: =TechDegAnn+WearAdder -> 0.006 | G37: Selected technology plus wear.
A38: Analysis horizon and module life | B38: years | C38: 20 | G38: Earlier ROI model: 20 years. Tables are built for 20 years.
A39: Inverter replacement | B39: ₹ / kWp | C39: 4000 | G39: Assumption.
A40: Inverter replacement year | B40: year | C40: 12 | G40: Assumption.
A41: Annual O&M (cleaning, inspection, minor repairs) | B41: % of capex / yr | C41: 0.015 | G41: Earlier ROI model.
A43: 3. Prices and costs (ex-GST)
...

Sheet Module Tech
A1: Module technology library (2026)
A2: Pick the technology on 'Product & Costs'. TOPCon is now the mainstream cell; PERC is being phased out; Reliance makes HJT modules at Jamnagar.
B5: Technology | C5: Cell efficiency (mass prod.) | D5: Best cells (2026) | E5: Module efficiency | F5: Temp. coefficient (%/°C) | G5: Year-1 degradation | H5: Annual degradation | I5: Module price, India (₹/Wp) | J5: Notes | K5: Sources
B6: Mono PERC (p-type) | C6: 0.233 | D6: Mature; no longer advancing | E6: 0.212 | F6: -0.0035 | G6: 0.02 | H6: 0.005 | I6: 13.8 | J6: Being phased out; TOPCon premium over PERC has collapsed to about 0-10%. | K6: JMK Research Apr 2026 (ex-works, 500 Wp); 2026 technology comparisons.
B7: TOPCon (n-type) | C7: 0.258 | D7: 26.66% industrial M10 cell (JinkoSolar, Feb 2026); 27.79% lab cell (ISFH-certified) | E7: 0.235 | F7: -0.0029 | G7: 0.01 | H7: 0.004 | I7: 14.2 | J7: About two-thirds of global capacity; commercial modules 22.5-24.8%, best 25.91%. DCR TOPCon ₹22.3/Wp. | K7: pv-magazine (25 Feb 2026); taiyangnews; Canadian Solar TOPHiKu6 and Jinko Tiger Neo datasheets (−0.29%/°C, 1% then 0.4%/yr); JMK Apr 2026.
B8: HJT (n-type) | C8: 0.258 | D8: Lowest temperature loss of the three | E8: 0.24 | F8: -0.0025 | G8: 0.01 | H8: 0.003 | I8: premium | J8: Commercial modules 23-25%; price premium over TOPCon. Reliance produces HJT modules at Jamnagar. | K8: 2026 technology comparisons (−0.24 to −0.26%/°C; 0.25-0.375%/yr).
A11: What each technology means for this walkway (selected scenario; pilot size, same rated power)
B12: Technology | C12: Temperature loss | D12: Performance ratio | E12: Specific yield (kWh/kWp/yr) | F12: Pilot year-1 kWh | G12: Pilot 20-year kWh | H12: Technology-derived module (W) | I12: Walkway W/m² (derived) | J12: Reading
B13: =B6 -> Mono PERC (p-type) | C13: =-F6*(Tcell-25) -> 0.0945 | D13: =(1-C13)*(1-LossSoil)*(1-LossFoot)*(1-LossRefl)*(1-LossMism)*(1-LossInv)*(1-LossAvail) -> 0.71887518 | E13: =SunYear*D13*(1-ShadeLoss) -> 1321.6089 | F13: =E13*PilotKWp*(1-G6) -> 4144.5655 | G13: =F13*SUMPRODUCT((1-H6-WearAdder)^(ROW($A$1:$A$20)-1)) -> 77603.817 | H13: =ModArea*E6*(1-WalkPackLoss)*1000 -> 39.644 | I13: =H13*ModPerM2 -> 158.576 | J13: PERC loses the most to heat on a hot, flat walkway.
B14: =B7 -> TOPCon (n-type) | C14: =-F7*(Tcell-25) -> 0.0783 | D14: =(1-C14)*(1-LossSoil)*(1-LossFoot)*(1-LossRefl)*(1-LossMism)*(1-LossInv)*(1-LossAvail) -> 0.73173634 | E14: =SunYear*D14*(1-ShadeLoss) -> 1345.2534 | F14: =E14*PilotKWp*(1-G7) -> 4261.7626 | G14: =F14*SUMPRODUCT((1-H7-WearAdder)^(ROW($A$1:$A$20)-1)) -> 80547.37 | H14: =ModArea*E7*(1-WalkPackLoss)*1000 -> 43.945 | I14: =H14*ModPerM2 -> 175.78 | J14: TOPCon: the default. Lower heat loss and slower ageing than PERC at a similar price.
B15: =B8 -> HJT (n-type) | C15: =-F8*(Tcell-25) -> 0.0675 | D15: =(1-C15)*(1-LossSoil)*(1-LossFoot)*(1-LossRefl)*(1-LossMism)*(1-LossInv)*(1-LossAvail) -> 0.74031045 | E15: =SunYear*D15*(1-ShadeLoss) -> 1361.0163 | F15: =E15*PilotKWp*(1-G8) -> 4311.6998 | G15: =F15*SUMPRODUCT((1-H8-WearAdder)^(ROW($A$1:$A$20)-1)) -> 82258.194 | H15: =ModArea*E8*(1-WalkPackLoss)*1000 -> 44.88 | I15: =H15*ModPerM2 -> 179.52 | J15: HJT: lowest heat loss; worth testing with Reliance's own Jamnagar cells.
B17: Pilot year-1 kWh includes first-year degradation. The derived module rating is an upgrade path to be validated; the client price is quoted on the 40 W design basis.

Sheet Irradiance
A1: Sunshine library: monthly global horizontal irradiance (kWh/m²/day)
A2: Pick the city on 'Client'. Values are typical-year climatology; replace with site data (Global Solar Atlas / NASA POWER) after the site walk.
B5: City | C5: Jan | D5: Feb | E5: Mar | F5: Apr | G5: May | H5: Jun | I5: Jul | J5: Aug | K5: Sep | L5: Oct | M5: Nov | N5: Dec | O5: kWh/m²/yr | P5: Avg / day | Q5: Source and confidence
B6: Days in month | C6: 31 | D6: 28 | E6: 31 | F6: 30 | G6: 31 | H6: 30 | I6: 31 | J6: 31 | K6: 30 | L6: 31 | M6: 30 | N6: 31
B7: Mumbai | C7: 4.8 | D7: 5.6 | E7: 6.3 | F7: 6.7 | G7: 6.7 | H7: 4.6 | I7: 3.7 | J7: 3.8 | K7: 4.5 | L7: 5.1 | M7: 4.8 | N7: 4.6 | O7: =SUMPRODUCT(C7:N7,$C$6:$N$6) -> 1859.8 | P7: =O7/365 -> 5.0953425 | Q7: Calibrated to NASA-derived Navi Mumbai data (annual mean 5.16, Jan 4.74, Jul 3.68 kWh/m²/day) and Meteonorm 8.2 (1,814 kWh/m²/yr). Earlier ROI model: 5.3 average.
B8: Bengaluru | C8: 5.4 | D8: 6.2 | E8: 6.6 | F8: 6.5 | G8: 6 | H8: 4.8 | I8: 4.3 | J8: 4.6 | K8: 5 | L8: 4.8 | M8: 4.6 | N8: 4.9 | O8: =SUMPRODUCT(C8:N8,$C$6:$N$6) -> 1935.2 | P8: =O8/365 -> 5.3019178 | Q8: Indicative typical year.
B9: Chennai | C9: 5 | D9: 6 | E9: 6.6 | F9: 6.7 | G9: 6.4 | H9: 5.6 | I9: 5.1 | J9: 5.3 | K9: 5.4 | L9: 4.6 | M9: 4 | N9: 4.1 | O9: =SUMPRODUCT(C9:N9,$C$6:$N$6) -> 1969.1 | P9: =O9/365 -> 5.3947945 | Q9: Indicative typical year.
B10: Hyderabad | C10: 5 | D10: 5.8 | E10: 6.4 | F10: 6.7 | G10: 6.6 | H10: 5.2 | I10: 4.5 | J10: 4.6 | K10: 4.9 | L10: 4.9 | M10: 4.7 | N10: 4.6 | O10: =SUMPRODUCT(C10:N10,$C$6:$N$6) -> 1942 | P10: =O10/365 -> 5.3205479 | Q10: Indicative typical year.
B11: Delhi NCR | C11: 3.6 | D11: 4.6 | E11: 5.8 | F11: 6.7 | G11: 7 | H11: 6.4 | I11: 5.4 | J11: 5.1 | K11: 5.3 | L11: 4.9 | M11: 4 | N11: 3.4 | O11: =SUMPRODUCT(C11:N11,$C$6:$N$6) -> 1892 | P11: =O11/365 -> 5.1835616 | Q11: Indicative typical year.
B12: Pune | C12: 5.2 | D12: 6 | E12: 6.6 | F12: 6.8 | G12: 6.7 | H12: 4.8 | I12: 3.8 | J12: 4 | K12: 4.7 | L12: 5 | M12: 4.9 | N12: 4.8 | O12: =SUMPRODUCT(C12:N12,$C$6:$N$6) -> 1923.1 | P12: =O12/365 -> 5.2687671 | Q12: Indicative typical year.
B13: Ahmedabad | C13: 4.6 | D13: 5.4 | E13: 6.3 | F13: 6.9 | G13: 7.1 | H13: 6.2 | I13: 4.8 | J13: 4.6 | K13: 5.4 | L13: 5.3 | M13: 4.6 | N13: 4.3 | O13: =SUMPRODUCT(C13:N13,$C$6:$N$6) -> 1991.2 | P13: =O13/365 -> 5.4553425 | Q13: Indicative typical year.
B14: Jamnagar | C14: 4.8 | D14: 5.6 | E14: 6.5 | F14: 7 | G14: 7.2 | H14: 6.3 | I14: 4.9 | J14: 4.8 | K14: 5.6 | L14: 5.5 | M14: 4.8 | N14: 4.5 | O14: =SUMPRODUCT(C14:N14,$C$6:$N$6) -> 2052 | P14: =O14/365 -> 5.6219178 | Q14: Indicative typical year.
B15: Kolkata | C15: 4.2 | D15: 4.9 | E15: 5.6 | F15: 6.1 | G15: 6 | H15: 4.8 | I15: 4.3 | J15: 4.4 | K15: 4.3 | L15: 4.4 | M15: 4.3 | N15: 4 | O15: =SUMPRODUCT(C15:N15,$C$6:$N$6) -> 1742.1 | P15: =O15/365 -> 4.7728767 | Q15: Indicative typical year.

Sheet Energy
A1: Energy: what the walkway generates
A2: Monthly generation for the pilot at the chosen city, after performance ratio and site shading.
A4: Pilot size
A5: Pilot area (m²) | D5: =PilotArea -> 20
A6: Modules | D6: =PilotArea*ModPerM2 -> 80
A7: Rated power (kWp) | D7: =PilotArea*PowerDens/1000 -> 3.2
A8: Sunshine profile | D8: =IrrCity -> Bengaluru
A10: Month | B10: Days | C10: Sunshine (kWh/m²/day) | D10: Sunshine (kWh/m²/month) | E10: Pilot generation (kWh) | F10: Per m² (kWh) | G10: Per day (kWh)
A11: Jan | B11: 31 | C11: =INDEX(Irradiance!C$7:C$15,MATCH(IrrCity,Irradiance!$B$7:$B$15,0)) -> 5.4 | D11: =C11*B11 -> 167.4 | E11: =D11*PilotKWp*PR*(1-ShadeLoss) -> 372.3777 | F11: =E11/PilotArea -> 18.618885 | G11: =E11/B11 -> 12.012184
A12: Feb | B12: 28 | C12: =INDEX(Irradiance!D$7:D$15,MATCH(IrrCity,Irradiance!$B$7:$B$15,0)) -> 6.2 | D12: =C12*B12 -> 173.6 | E12: =D12*PilotKWp*PR*(1-ShadeLoss) -> 386.16946 | F12: =E12/PilotArea -> 19.308473 | G12: =E12/B12 -> 13.791767
A13: Mar | B13: 31 | C13: =INDEX(Irradiance!E$7:E$15,MATCH(IrrCity,Irradiance!$B$7:$B$15,0)) -> 6.6 | D13: =C13*B13 -> 204.6 | E13: =D13*PilotKWp*PR*(1-ShadeLoss) -> 455.1283 | F13: =E13/PilotArea -> 22.756415 | G13: =E13/B13 -> 14.681558
A14: Apr | B14: 30 | C14: =INDEX(Irradiance!F$7:F$15,MATCH(IrrCity,Irradiance!$B$7:$B$15,0)) -> 6.5 | D14: =C14*B14 -> 195 | E14: =D14*PilotKWp*PR*(1-ShadeLoss) -> 433.7733 | F14: =E14/PilotArea -> 21.688665 | G14: =E14/B14 -> 14.45911
A15: May | B15: 31 | C15: =INDEX(Irradiance!G$7:G$15,MATCH(IrrCity,Irradiance!$B$7:$B$15,0)) -> 6 | D15: =C15*B15 -> 186 | E15: =D15*PilotKWp*PR*(1-ShadeLoss) -> 413.753 | F15: =E15/PilotArea -> 20.68765 | G15: =E15/B15 -> 13.346871
A16: Jun | B16: 30 | C16: =INDEX(Irradiance!H$7:H$15,MATCH(IrrCity,Irradiance!$B$7:$B$15,0)) -> 4.8 | D16: =C16*B16 -> 144 | E16: =D16*PilotKWp*PR*(1-ShadeLoss) -> 320.3249 | F16: =E16/PilotArea -> 16.016245 | G16: =E16/B16 -> 10.677497
A17: Jul | B17: 31 | C17: =INDEX(Irradiance!I$7:I$15,MATCH(IrrCity,Irradiance!$B$7:$B$15,0)) -> 4.3 | D17: =C17*B17 -> 133.3 | E17: =D17*PilotKWp*PR*(1-ShadeLoss) -> 296.52298 | F17: =E17/PilotArea -> 14.826149 | G17: =E17/B17 -> 9.5652574
A18: Aug | B18: 31 | C18: =INDEX(Irradiance!J$7:J$15,MATCH(IrrCity,Irradiance!$B$7:$B$15,0)) -> 4.6 | D18: =C18*B18 -> 142.6 | E18: =D18*PilotKWp*PR*(1-ShadeLoss) -> 317.21063 | F18: =E18/PilotArea -> 15.860532 | G18: =E18/B18 -> 10.232601
A19: Sep | B19: 30 | C19: =INDEX(Irradiance!K$7:K$15,MATCH(IrrCity,Irradiance!$B$7:$B$15,0)) -> 5 | D19: =C19*B19 -> 150 | E19: =D19*PilotKWp*PR*(1-ShadeLoss) -> 333.67177 | F19: =E19/PilotArea -> 16.683589 | G19: =E19/B19 -> 11.122392
A20: Oct | B20: 31 | C20: =INDEX(Irradiance!L$7:L$15,MATCH(IrrCity,Irradiance!$B$7:$B$15,0)) -> 4.8 | D20: =C20*B20 -> 148.8 | E20: =D20*PilotKWp*PR*(1-ShadeLoss) -> 331.0024 | F20: =E20/PilotArea -> 16.55012 | G20: =E20/B20 -> 10.677497
A21: Nov | B21: 30 | C21: =INDEX(Irradiance!M$7:M$15,MATCH(IrrCity,Irradiance!$B$7:$B$15,0)) -> 4.6 | D21: =C21*B21 -> 138 | E21: =D21*PilotKWp*PR*(1-ShadeLoss) -> 306.97803 | F21: =E21/PilotArea -> 15.348901 | G21: =E21/B21 -> 10.232601
A22: Dec | B22: 31 | C22: =INDEX(Irradiance!N$7:N$15,MATCH(IrrCity,Irradiance!$B$7:$B$15,0)) -> 4.9 | D22: =C22*B22 -> 151.9 | E22: =D22*PilotKWp*PR*(1-ShadeLoss) -> 337.89828 | F22: =E22/PilotArea -> 16.894914 | G22: =E22/B22 -> 10.899945
A23: Year 1* | B23: =SUM(B11:B22) -> 365 | D23: =SUM(D11:D22) -> 1935.2 | E23: =SUM(E11:E22) -> 4304.8107 | F23: =SUM(F11:F22) -> 215.24054 | G23: =E23/365 -> 11.794002
A24: * Before first-year degradation; the cash-flow sheets apply it.
A25: Key energy figures
A26: Specific yield (kWh per kWp per year) | D26: =SunYear*PR*(1-ShadeLoss) -> 1345.2534
A27: Generation per m² per day, average (kWh) | D27: =KWhPerM2/365 -> 0.5897001
A28: Best month (kWh) | D28: =MAX(E11:E22) -> 455.1283
A29: Weakest month (kWh) | D29: =MIN(E11:E22) -> 296.52298
A30: CO2 avoided in year 1 (kg) | D30: =PilotKWh1*GridEF -> 3056.4156
A31: Recycled PP in the pilot base (kg) | D31: =PilotArea*PlasticLW -> 80

Sheet Pilot BoQ
A1: Pilot bill of quantities and offer
A2: List = GridMats standard value. 'GridMats contributes' = what the pilot offer covers. Ex-GST unless stated.
A4: Item | B4: Qty | C4: Unit | D4: Rate (₹) | E4: List value (₹) | F4: GridMats contributes (₹) | G4: Client pays (₹) | H4: Note
A5: Site assessment, shading study and engineering design | B5: 1 | C5: lot | D5: =DesignLump -> 40000 | E5: =B5*D5 -> 40000 | F5: =E5 -> 40000 | G5: =E5-F5 -> 0 | H5: Included
A6: Base works: new walkway (subgrade, open-graded GSB, bedding, edges) or overlay levelling and ramps | B6: =PilotArea -> 20 | C6: m² | D6: =IF(BuildType="New walkway",CivilNew,CivilOverlay) -> 268 | E6: =B6*D6 -> 5360 | F6: 0 | G6: =E6-F6 -> 5360
A7: GridMats OC-LW 40 structural base (100% recycled PP), 4 grids per m² | B7: =PilotArea -> 20 | C7: m² | D7: =GridT1 -> 690 | E7: =B7*D7 -> 13800 | F7: 0 | G7: =E7-F7 -> 13800
A8: Walkable PV layer: 40 W modules, 12 mm toughened glass, MLP lumber with wiring | B8: =PilotArea -> 20 | C8: m² | D8: =PVPilot -> 9500 | E8: =B8*D8 -> 190000 | F8: =E8*CoFund -> 95000 | G8: =E8-F8 -> 95000 | H8: Co-funded by GridMats
A9: MLP lumber layer (only if priced separately) | B9: =PilotArea -> 20 | C9: m² | D9: =MLPExtra -> 0 | E9: =B9*D9 -> 0 | F9: 0 | G9: =E9-F9 -> 0
A10: Electrical BOS: inverter, DC/AC cabling, protection, earthing | B10: =PilotKWp*1000 -> 3200 | C10: Wp | D10: =BOSWp -> 8 | E10: =B10*D10 -> 25600 | F10: 0 | G10: =E10-F10 -> 25600
A11: Logistics and freight | B11: =SUM(E6:E10) -> 234760 | C11: ₹ | D11: =LogPct -> 0.05 | E11: =B11*D11 -> 11738 | F11: 0 | G11: =E11-F11 -> 11738 | H11: % of hardware
A12: Grid integration and metering | B12: 1 | C12: lot | D12: =IntegLump -> 25000 | E12: =B12*D12 -> 25000 | F12: 0 | G12: =E12-F12 -> 25000
A13: Installation labour | B13: =PilotArea -> 20 | C13: m² | D13: =InstallM2 -> 300 | E13: =B13*D13 -> 6000 | F13: 0 | G13: =E13-F13 -> 6000 | H13: Built by teams GridMats trains
A14: GridMats supervision and training on site | B14: =SupDays -> 3 | C14: days | D14: =ManDay -> 15000 | E14: =B14*D14 -> 45000 | F14: =E14 -> 45000 | G14: =E14-F14 -> 0 | H14: Included
A15: Supervisor travel and stay | B15: 1 | C15: lot | D15: =TravelLump -> 40000 | E15: =B15*D15 -> 40000 | F15: =E15 -> 40000 | G15: =E15-F15 -> 0 | H15: Included
A16: IoT sensors, live dashboard and performance study | B16: 1 | C16: lot | D16: =IoTPkg -> 125000 | E16: =B16*D16 -> 125000 | F16: =E16 -> 125000 | G16: =E16-F16 -> 0 | H16: Included
A17: Total (ex-GST) | E17: =SUM(E5:E16) -> 527498 | F17: =SUM(F5:F16) -> 345000 | G17: =SUM(G5:G16) -> 182498
A18: GST on what the client pays | D18: =GSTRate -> 0.089 | G18: =G17*D18 -> 16242.322
A19: Client pays, including GST | G19: =G17+G18 -> 198740.32
A21: Summary
A22: Physical installed cost of the pilot, list (hardware, logistics, integration, installation) | G22: =SUMPRODUCT(E5:E16,--(H5:H16<>"Included")) -> 277498
A23: Physical installed cost per sq ft (₹) | G23: =PilotPhys/(PilotArea*10.7639) -> 1289.0216
A24: Physical installed cost per m² (₹) | G24: =PilotPhys/PilotArea -> 13874.9
A25: Physical installed cost per kWp (₹) | G25: =PilotPhys/PilotKWp -> 86718.125
A26: Client pays per sq ft, ex-GST (₹) | G26: =PilotPays/(PilotArea*10.7639) -> 847.73177
A27: GridMats contribution as a share of list | G27: =PilotContrib/PilotList -> 0.65403092
A28: PV layer price per sq ft, pilot (₹) | G28: =PVPilot/10.7639 -> 882.57973

Sheet Pilot Economics
A1: Pilot economics
A2: Two views: on what the client actually pays (with GridMats co-funding), and on the full physical cost (no co-funding).
A4: Client's pilot outlay, ex-GST (₹) | H4: =PilotPays -> 182498
A5: Full physical installed cost, ex-GST (₹) | H5: =PilotPhys -> 277498
A6: Year-1 generation (kWh) | H6: =PilotKWh1 -> 4304.8107
A7: O&M is charged on the physical installed cost in both views. GST is excluded on the assumption that the client claims input tax credit.
A9: A. On the client's outlay (pilot offer)
A10: Year | B10: Degradation factor | C10: Generation (kWh) | D10: Tariff (₹/kWh) | E10: Savings (₹) | F10: O&M (₹) | G10: Inverter (₹) | H10: Net cash flow (₹) | I10: Cumulative (₹) | J10: Discount factor | K10: Discounted CF (₹) | L10: Cumulative discounted (₹)
A11: 0 | H11: =-PilotPays -> -182498 | I11: =H11 -> -182498 | J11: 1 | K11: =H11*J11 -> -182498 | L11: =K11 -> -182498
A12: 1 | B12: =IF(A12<=Life,(1-Deg1)*(1-Degr)^(A12-1),0) -> 0.99 | C12: =PilotKWh1*B12 -> 4261.7626 | D12: =Tariff*(1+TariffEsc)^(A12-1) -> 9 | E12: =C12*D12 -> 38355.864 | F12: =IF(A12<=Life,-OMPct*PilotPhys,0) -> -4162.47 | G12: =IF(AND(A12=InvYear,InvYear<Life),-InvRepl*PilotKWp,0) -> 0 | H12: =E12+F12+G12 -> 34193.394 | I12: =I11+H12 -> -148304.61 | J12: =1/(1+DiscRate)^A12 -> 0.90909091 | K12: =H12*J12 -> 31084.903 | L12: =L11+K12 -> -151413.1
A13: 2 | B13: =IF(A13<=Life,(1-Deg1)*(1-Degr)^(A13-1),0) -> 0.98406 | C13: =PilotKWh1*B13 -> 4236.1921 | D13: =Tariff*(1+TariffEsc)^(A13-1) -> 9.27 | E13: =C13*D13 -> 39269.5 | F13: =IF(A13<=Life,-OMPct*PilotPhys,0) -> -4162.47 | G13: =IF(AND(A13=InvYear,InvYear<Life),-InvRepl*PilotKWp,0) -> 0 | H13: =E13+F13+G13 -> 35107.03 | I13: =I12+H13 -> -113197.58 | J13: =1/(1+DiscRate)^A13 -> 0.82644628 | K13: =H13*J13 -> 29014.075 | L13: =L12+K13 -> -122399.02
A14: 3 | B14: =IF(A14<=Life,(1-Deg1)*(1-Degr)^(A14-1),0) -> 0.97815564 | C14: =PilotKWh1*B14 -> 4210.7749 | D14: =Tariff*(1+TariffEsc)^(A14-1) -> 9.5481 | E14: =C14*D14 -> 40204.9 | F14: =IF(A14<=Life,-OMPct*PilotPhys,0) -> -4162.47 | G14: =IF(AND(A14=InvYear,InvYear<Life),-InvRepl*PilotKWp,0) -> 0 | H14: =E14+F14+G14 -> 36042.43 | I14: =I13+H14 -> -77155.146 | J14: =1/(1+DiscRate)^A14 -> 0.7513148 | K14: =H14*J14 -> 27079.211 | L14: =L13+K14 -> -95319.811
A15: 4 | B15: =IF(A15<=Life,(1-Deg1)*(1-Degr)^(A15-1),0) -> 0.97228671 | C15: =PilotKWh1*B15 -> 4185.5103 | D15: =Tariff*(1+TariffEsc)^(A15-1) -> 9.834543 | E15: =C15*D15 -> 41162.581 | F15: =IF(A15<=Life,-OMPct*PilotPhys,0) -> -4162.47 | G15: =IF(AND(A15=InvYear,InvYear<Life),-InvRepl*PilotKWp,0) -> 0 | H15: =E15+F15+G15 -> 37000.111 | I15: =I14+H15 -> -40155.035 | J15: =1/(1+DiscRate)^A15 -> 0.68301346 | K15: =H15*J15 -> 25271.573 | L15: =L14+K15 -> -70048.237
A16: 5 | B16: =IF(A16<=Life,(1-Deg1)*(1-Degr)^(A16-1),0) -> 0.96645299 | C16: =PilotKWh1*B16 -> 4160.3972 | D16: =Tariff*(1+TariffEsc)^(A16-1) -> 10.129579 | E16: =C16*D16 -> 42143.073 | F16: =IF(A16<=Life,-OMPct*PilotPhys,0) -> -4162.47 | G16: =IF(AND(A16=InvYear,InvYear<Life),-InvRepl*PilotKWp,0) -> 0 | H16: =E16+F16+G16 -> 37980.603 | I16: =I15+H16 -> -2174.4319 | J16: =1/(1+DiscRate)^A16 -> 0.62092132 | K16: =H16*J16 -> 23582.966 | L16: =L15+K16 -> -46465.271
A17: 6 | B17: =IF(A17<=Life,(1-Deg1)*(1-Degr)^(A17-1),0) -> 0.96065427 | C17: =PilotKWh1*B17 -> 4135.4348 | D17: =Tariff*(1+TariffEsc)^(A17-1) -> 10.433467 | E17: =C17*D17 -> 43146.921 | F17: =IF(A17<=Life,-OMPct*PilotPhys,0) -> -4162.47 | G17: =IF(AND(A17=InvYear,InvYear<Life),-InvRepl*PilotKWp,0) -> 0 | H17: =E17+F17+G17 -> 38984.451 | I17: =I16+H17 -> 36810.019 | J17: =1/(1+DiscRate)^A17 -> 0.56447393 | K17: =H17*J17 -> 22005.706 | L17: =L16+K17 -> -24459.564
A18: 7 | B18: =IF(A18<=Life,(1-Deg1)*(1-Degr)^(A18-1),0) -> 0.95489034 | C18: =PilotKWh1*B18 -> 4110.6222 | D18: =Tariff*(1+TariffEsc)^(A18-1) -> 10.746471 | E18: =C18*D18 -> 44174.681 | F18: =IF(A18<=Life,-OMPct*PilotPhys,0) -> -4162.47 | G18: =IF(AND(A18=InvYear,InvYear<Life),-InvRepl*PilotKWp,0) -> 0 | H18: =E18+F18+G18 -> 40012.211 | I18: =I17+H18 -> 76822.23 | J18: =1/(1+DiscRate)^A18 -> 0.51315812 | K18: =H18*J18 -> 20532.591 | L18: =L17+K18 -> -3926.9735
A19: 8 | B19: =IF(A19<=Life,(1-Deg1)*(1-Degr)^(A19-1),0) -> 0.949161 | C19: =PilotKWh1*B19 -> 4085.9585 | D19: =Tariff*(1+TariffEsc)^(A19-1) -> 11.068865 | E19: =C19*D19 -> 45226.922 | F19: =IF(A19<=Life,-OMPct*PilotPhys,0) -> -4162.47 | G19: =IF(AND(A19=InvYear,InvYear<Life),-InvRepl*PilotKWp,0) -> 0 | H19: =E19+F19+G19 -> 41064.452 | I19: =I18+H19 -> 117886.68 | J19: =1/(1+DiscRate)^A19 -> 0.46650738 | K19: =H19*J19 -> 19156.87 | L19: =L18+K19 -> 15229.896
A20: 9 | B20: =IF(A20<=Life,(1-Deg1)*(1-Degr)^(A20-1),0) -> 0.94346603 | C20: =PilotKWh1*B20 -> 4061.4427 | D20: =Tariff*(1+TariffEsc)^(A20-1) -> 11.400931 | E20: =C20*D20 -> 46304.227 | F20: =IF(A20<=Life,-OMPct*PilotPhys,0) -> -4162.47 | G20: =IF(AND(A20=InvYear,InvYear<Life),-InvRepl*PilotKWp,0) -> 0 | H20: =E20+F20+G20 -> 42141.757 | I20: =I19+H20 -> 160028.44 | J20: =1/(1+DiscRate)^A20 -> 0.42409762 | K20: =H20*J20 -> 17872.219 | L20: =L19+K20 -> 33102.115
A21: 10 | B21: =IF(A21<=Life,(1-Deg1)*(1-Degr)^(A21-1),0) -> 0.93780524 | C21: =PilotKWh1*B21 -> 4037.0741 | D21: =Tariff*(1+TariffEsc)^(A21-1) -> 11.742959 | E21: =C21*D21 -> 47407.194 | F21: =IF(A21<=Life,-OMPct*PilotPhys,0) -> -4162.47 | G21: =IF(AND(A21=InvYear,InvYear<Life),-InvRepl*PilotKWp,0) -> 0 | H21: =E21+F21+G21 -> 43244.724 | I21: =I20+H21 -> 203273.16 | J21: =1/(1+DiscRate)^A21 -> 0.38554329 | K21: =H21*J21 -> 16672.713 | L21: =L20+K21 -> 49774.828
A22: 11 | B22: =IF(A22<=Life,(1-Deg1)*(1-Degr)^(A22-1),0) -> 0.93217841 | C22: =PilotKWh1*B22 -> 4012.8516 | D22: =Tariff*(1+TariffEsc)^(A22-1) -> 12.095247 | E22: =C22*D22 -> 48536.433 | F22: =IF(A22<=Life,-OMPct*PilotPhys,0) -> -4162.47 | G22: =IF(AND(A22=InvYear,InvYear<Life),-InvRepl*PilotKWp,0) -> 0 | H22: =E22+F22+G22 -> 44373.963 | I22: =I21+H22 -> 247647.13 | J22: =1/(1+DiscRate)^A22 -> 0.3504939 | K22: =H22*J22 -> 15552.803 | L22: =L21+K22 -> 65327.632
A23: 12 | B23: =IF(A23<=Life,(1-Deg1)*(1-Degr)^(A23-1),0) -> 0.92658534 | C23: =PilotKWh1*B23 -> 3988.7745 | D23: =Tariff*(1+TariffEsc)^(A23-1) -> 12.458105 | E23: =C23*D23 -> 49692.571 | F23: =IF(A23<=Life,-OMPct*PilotPhys,0) -> -4162.47 | G23: =IF(AND(A23=InvYear,InvYear<Life),-InvRepl*PilotKWp,0) -> -12800 | H23: =E23+F23+G23 -> 32730.101 | I23: =I22+H23 -> 280377.23 | J23: =1/(1+DiscRate)^A23 -> 0.31863082 | K23: =H23*J23 -> 10428.819 | L23: =L22+K23 -> 75756.451
... A31: 20 | B31: =IF(A31<=Life,(1-Deg1)*(1-Degr)^(A31-1),0) -> 0.88303211 | C31: =PilotKWh1*B31 -> 3801.2861 | D31: =Tariff*(1+TariffEsc)^(A31-1) -> 15.781554 | E31: =C31*D31 -> 59990.204 | F31: =IF(A31<=Life,-OMPct*PilotPhys,0) -> -4162.47 | G31: =IF(AND(A31=InvYear,InvYear<Life),-InvRepl*PilotKWp,0) -> 0 | H31: =E31+F31+G31 -> 55827.734 | I31: =I30+H31 -> 689685.48 | J31: =1/(1+DiscRate)^A31 -> 0.14864363 | K31: =H31*J31 -> 8298.437 | L31: =L30+K31 -> 161633.95
A33: Results: client's outlay
A34: Year-1 generation (kWh) | E34: =C12 -> 4261.7626
A35: Year-1 savings (₹) | E35: =E12 -> 38355.864
A36: Year-1 O&M (₹) | E36: =-F12 -> 4162.47
A37: Simple payback (years) | E37: =IF(COUNTIF(I12:I31,"<0")>=20,"> 20",COUNTIF(I12:I31,"<0")+(-INDEX(I11:I31,COUNTIF(I12:I31,"<0")+1))/INDEX(H11:H31,COUNTIF(I12:I31,"<0")+2)) -> 5.0557769
A38: Discounted payback (years) | E38: =IF(COUNTIF(L12:L31,"<0")>=20,"> 20",COUNTIF(L12:L31,"<0")+(-INDEX(L11:L31,COUNTIF(L12:L31,"<0")+1))/INDEX(K11:K31,COUNTIF(L12:L31,"<0")+2)) -> 7.2049904
A39: NPV over 20 years (₹) | E39: =L31 -> 161633.95
A40: IRR over 20 years | E40: =IFERROR(IRR(H11:H31),"n/a") -> 0.20486744
A41: 20-year net cash (₹) | E41: =I31 -> 689685.48
A42: Return on investment over 20 years (×) | E42: =IFERROR(I31/PilotPays,"n/a") -> 3.7791399
A45: B. On the full physical installed cost (no co-funding)
A46: Year | B46: Degradation factor | C46: Generation (kWh) | D46: Tariff (₹/kWh) | E46: Savings (₹) | F46: O&M (₹) | G46: Inverter (₹) | H46: Net cash flow (₹) | I46: Cumulative (₹) | J46: Discount factor | K46: Discounted CF (₹) | L46: Cumulative discounted (₹)
A47: 0 | H47: =-PilotPhys -> -277498 | I47: =H47 -> -277498 | J47: 1 | K47: =H47*J47 -> -277498 | L47: =K47 -> -277498
A48: 1 | B48: =IF(A48<=Life,(1-Deg1)*(1-Degr)^(A48-1),0) -> 0.99 | C48: =PilotKWh1*B48 -> 4261.7626 | D48: =Tariff*(1+TariffEsc)^(A48-1) -> 9 | E48: =C48*D48 -> 38355.864 | F48: =IF(A48<=Life,-OMPct*PilotPhys,0) -> -4162.47 | G48: =IF(AND(A48=InvYear,InvYear<Life),-InvRepl*PilotKWp,0) -> 0 | H48: =E48+F48+G48 -> 34193.394 | I48: =I47+H48 -> -243304.61 | J48: =1/(1+DiscRate)^A48 -> 0.90909091 | K48: =H48*J48 -> 31084.903 | L48: =L47+K48 -> -246413.1
A49: 2 | B49: =IF(A49<=Life,(1-Deg1)*(1-Degr)^(A49-1),0) -> 0.98406 | C49: =PilotKWh1*B49 -> 4236.1921 | D49: =Tariff*(1+TariffEsc)^(A49-1) -> 9.27 | E49: =C49*D49 -> 39269.5 | F49: =IF(A49<=Life,-OMPct*PilotPhys,0) -> -4162.47 | G49: =IF(AND(A49=InvYear,InvYear<Life),-InvRepl*PilotKWp,0) -> 0 | H49: =E49+F49+G49 -> 35107.03 | I49: =I48+H49 -> -208197.58 | J49: =1/(1+DiscRate)^A49 -> 0.82644628 | K49: =H49*J49 -> 29014.075 | L49: =L48+K49 -> -217399.02
A50: 3 | B50: =IF(A50<=Life,(1-Deg1)*(1-Degr)^(A50-1),0) -> 0.97815564 | C50: =PilotKWh1*B50 -> 4210.7749 | D50: =Tariff*(1+TariffEsc)^(A50-1) -> 9.5481 | E50: =C50*D50 -> 40204.9 | F50: =IF(A50<=Life,-OMPct*PilotPhys,0) -> -4162.47 | G50: =IF(AND(A50=InvYear,InvYear<Life),-InvRepl*PilotKWp,0) -> 0 | H50: =E50+F50+G50 -> 36042.43 | I50: =I49+H50 -> -172155.15 | J50: =1/(1+DiscRate)^A50 -> 0.7513148 | K50: =H50*J50 -> 27079.211 | L50: =L49+K50 -> -190319.81
A51: 4 | B51: =IF(A51<=Life,(1-Deg1)*(1-Degr)^(A51-1),0) -> 0.97228671 | C51: =PilotKWh1*B51 -> 4185.5103 | D51: =Tariff*(1+TariffEsc)^(A51-1) -> 9.834543 | E51: =C51*D51 -> 41162.581 | F51: =IF(A51<=Life,-OMPct*PilotPhys,0) -> -4162.47 | G51: =IF(AND(A51=InvYear,InvYear<Life),-InvRepl*PilotKWp,0) -> 0 | H51: =E51+F51+G51 -> 37000.111 | I51: =I50+H51 -> -135155.04 | J51: =1/(1+DiscRate)^A51 -> 0.68301346 | K51: =H51*J51 -> 25271.573 | L51: =L50+K51 -> -165048.24
A52: 5 | B52: =IF(A52<=Life,(1-Deg1)*(1-Degr)^(A52-1),0) -> 0.96645299 | C52: =PilotKWh1*B52 -> 4160.3972 | D52: =Tariff*(1+TariffEsc)^(A52-1) -> 10.129579 | E52: =C52*D52 -> 42143.073 | F52: =IF(A52<=Life,-OMPct*PilotPhys,0) -> -4162.47 | G52: =IF(AND(A52=InvYear,InvYear<Life),-InvRepl*PilotKWp,0) -> 0 | H52: =E52+F52+G52 -> 37980.603 | I52: =I51+H52 -> -97174.432 | J52: =1/(1+DiscRate)^A52 -> 0.62092132 | K52: =H52*J52 -> 23582.966 | L52: =L51+K52 -> -141465.27
...

Sheet Rollout Economics
A1: Rollout economics: campus walkway at rollout prices
A2: Uses the campus rollout area from 'Client'. No co-funding at rollout.
A4: Installed cost per m² at the rollout area
A5: Rollout area (m²) | H5: =CampusArea -> 1000
A6: Rated power (kWp) | H6: =RO_Area*PowerDens/1000 -> 160
A7: Base works (₹/m²) | H7: =IF(BuildType="New walkway",CivilNew,CivilOverlay) -> 268
A8: GridMats OC-LW 40 at this area (₹/m²) | H8: =IF(RO_Area<1000,GridT1,IF(RO_Area<2500,GridT2,IF(RO_Area<5000,GridT3,GridT4))) -> 650
A9: Walkable PV layer (₹/m²) | H9: =IF(RO_Area>=ScaleFrom,PVScale,PVPilot)+MLPExtra -> 8500
A10: Electrical BOS (₹/m²) | H10: =BOSWp*PowerDens -> 1280
A11: Logistics (₹/m²) | H11: =LogPct*(RO_Civil+RO_Grid+RO_PV+RO_BOS) -> 534.9
A12: Grid integration (₹/m²) | H12: =ROUNDUP(RO_KWp/ConnKWp,0)*IntegLump/RO_Area -> 100
A13: Installation (₹/m²) | H13: =InstallM2 -> 300
A14: Installed cost (₹/m²) | H14: =SUM(H7:H13) -> 11632.9
A15: Installed cost (₹/sq ft) | H15: =RO_CostM2/10.7639 -> 1080.7328
A16: Less: walkway it replaces (₹/m², new build only) | H16: =IF(BuildType="New walkway",ConvWalk,0) -> 1200
A17: Net extra cost for a generating walkway (₹/m²) | H17: =RO_CostM2-RO_Credit -> 10432.9
A18: Total installed cost (₹) | H18: =RO_CostM2*RO_Area -> 11632900
A19: Net investment after walkway credit (₹) | H19: =RO_NetM2*RO_Area -> 10432900
A20: Year-1 generation (kWh) | H20: =RO_KWp*SpecYield -> 215240.54
A21: Installed cost per kWp, solar part (₹) | H21: =(RO_PV+RO_BOS+RO_Log+RO_Integ)/(PowerDens/1000) -> 65093.125
A24: Year | B24: Degradation factor | C24: Generation (kWh) | D24: Tariff (₹/kWh) | E24: Savings (₹) | F24: O&M (₹) | G24: Inverter (₹) | H24: Net cash flow (₹) | I24: Cumulative (₹) | J24: Discount factor | K24: Discounted CF (₹) | L24: Cumulative discounted (₹)
A25: 0 | H25: =-RO_NetCapex -> -10432900 | I25: =H25 -> -10432900 | J25: 1 | K25: =H25*J25 -> -10432900 | L25: =K25 -> -10432900
A26: 1 | B26: =IF(A26<=Life,(1-Deg1)*(1-Degr)^(A26-1),0) -> 0.99 | C26: =RO_Gen1*B26 -> 213088.13 | D26: =Tariff*(1+TariffEsc)^(A26-1) -> 9 | E26: =C26*D26 -> 1917793.2 | F26: =IF(A26<=Life,-OMPct*RO_Capex,0) -> -174493.5 | G26: =IF(AND(A26=InvYear,InvYear<Life),-InvRepl*RO_KWp,0) -> 0 | H26: =E26+F26+G26 -> 1743299.7 | I26: =I25+H26 -> -8689600.3 | J26: =1/(1+DiscRate)^A26 -> 0.90909091 | K26: =H26*J26 -> 1584817.9 | L26: =L25+K26 -> -8848082.1
A27: 2 | B27: =IF(A27<=Life,(1-Deg1)*(1-Degr)^(A27-1),0) -> 0.98406 | C27: =RO_Gen1*B27 -> 211809.6 | D27: =Tariff*(1+TariffEsc)^(A27-1) -> 9.27 | E27: =C27*D27 -> 1963475 | F27: =IF(A27<=Life,-OMPct*RO_Capex,0) -> -174493.5 | G27: =IF(AND(A27=InvYear,InvYear<Life),-InvRepl*RO_KWp,0) -> 0 | H27: =E27+F27+G27 -> 1788981.5 | I27: =I26+H27 -> -6900618.8 | J27: =1/(1+DiscRate)^A27 -> 0.82644628 | K27: =H27*J27 -> 1478497.1 | L27: =L26+K27 -> -7369585
A28: 3 | B28: =IF(A28<=Life,(1-Deg1)*(1-Degr)^(A28-1),0) -> 0.97815564 | C28: =RO_Gen1*B28 -> 210538.75 | D28: =Tariff*(1+TariffEsc)^(A28-1) -> 9.5481 | E28: =C28*D28 -> 2010245 | F28: =IF(A28<=Life,-OMPct*RO_Capex,0) -> -174493.5 | G28: =IF(AND(A28=InvYear,InvYear<Life),-InvRepl*RO_KWp,0) -> 0 | H28: =E28+F28+G28 -> 1835751.5 | I28: =I27+H28 -> -5064867.3 | J28: =1/(1+DiscRate)^A28 -> 0.7513148 | K28: =H28*J28 -> 1379227.3 | L28: =L27+K28 -> -5990357.7
A29: 4 | B29: =IF(A29<=Life,(1-Deg1)*(1-Degr)^(A29-1),0) -> 0.97228671 | C29: =RO_Gen1*B29 -> 209275.51 | D29: =Tariff*(1+TariffEsc)^(A29-1) -> 9.834543 | E29: =C29*D29 -> 2058129 | F29: =IF(A29<=Life,-OMPct*RO_Capex,0) -> -174493.5 | G29: =IF(AND(A29=InvYear,InvYear<Life),-InvRepl*RO_KWp,0) -> 0 | H29: =E29+F29+G29 -> 1883635.5 | I29: =I28+H29 -> -3181231.8 | J29: =1/(1+DiscRate)^A29 -> 0.68301346 | K29: =H29*J29 -> 1286548.4 | L29: =L28+K29 -> -4703809.3
A30: 5 | B30: =IF(A30<=Life,(1-Deg1)*(1-Degr)^(A30-1),0) -> 0.96645299 | C30: =RO_Gen1*B30 -> 208019.86 | D30: =Tariff*(1+TariffEsc)^(A30-1) -> 10.129579 | E30: =C30*D30 -> 2107153.7 | F30: =IF(A30<=Life,-OMPct*RO_Capex,0) -> -174493.5 | G30: =IF(AND(A30=InvYear,InvYear<Life),-InvRepl*RO_KWp,0) -> 0 | H30: =E30+F30+G30 -> 1932660.2 | I30: =I29+H30 -> -1248571.6 | J30: =1/(1+DiscRate)^A30 -> 0.62092132 | K30: =H30*J30 -> 1200029.9 | L30: =L29+K30 -> -3503779.4
A31: 6 | B31: =IF(A31<=Life,(1-Deg1)*(1-Degr)^(A31-1),0) -> 0.96065427 | C31: =RO_Gen1*B31 -> 206771.74 | D31: =Tariff*(1+TariffEsc)^(A31-1) -> 10.433467 | E31: =C31*D31 -> 2157346.1 | F31: =IF(A31<=Life,-OMPct*RO_Capex,0) -> -174493.5 | G31: =IF(AND(A31=InvYear,InvYear<Life),-InvRepl*RO_KWp,0) -> 0 | H31: =E31+F31+G31 -> 1982852.6 | I31: =I30+H31 -> 734280.97 | J31: =1/(1+DiscRate)^A31 -> 0.56447393 | K31: =H31*J31 -> 1119268.6 | L31: =L30+K31 -> -2384510.8
A32: 7 | B32: =IF(A32<=Life,(1-Deg1)*(1-Degr)^(A32-1),0) -> 0.95489034 | C32: =RO_Gen1*B32 -> 205531.11 | D32: =Tariff*(1+TariffEsc)^(A32-1) -> 10.746471 | E32: =C32*D32 -> 2208734 | F32: =IF(A32<=Life,-OMPct*RO_Capex,0) -> -174493.5 | G32: =IF(AND(A32=InvYear,InvYear<Life),-InvRepl*RO_KWp,0) -> 0 | H32: =E32+F32+G32 -> 2034240.5 | I32: =I31+H32 -> 2768521.5 | J32: =1/(1+DiscRate)^A32 -> 0.51315812 | K32: =H32*J32 -> 1043887.1 | L32: =L31+K32 -> -1340623.8
A33: 8 | B33: =IF(A33<=Life,(1-Deg1)*(1-Degr)^(A33-1),0) -> 0.949161 | C33: =RO_Gen1*B33 -> 204297.92 | D33: =Tariff*(1+TariffEsc)^(A33-1) -> 11.068865 | E33: =C33*D33 -> 2261346.1 | F33: =IF(A33<=Life,-OMPct*RO_Capex,0) -> -174493.5 | G33: =IF(AND(A33=InvYear,InvYear<Life),-InvRepl*RO_KWp,0) -> 0 | H33: =E33+F33+G33 -> 2086852.6 | I33: =I32+H33 -> 4855374.1 | J33: =1/(1+DiscRate)^A33 -> 0.46650738 | K33: =H33*J33 -> 973532.14 | L33: =L32+K33 -> -367091.61
A34: 9 | B34: =IF(A34<=Life,(1-Deg1)*(1-Degr)^(A34-1),0) -> 0.94346603 | C34: =RO_Gen1*B34 -> 203072.14 | D34: =Tariff*(1+TariffEsc)^(A34-1) -> 11.400931 | E34: =C34*D34 -> 2315211.4 | F34: =IF(A34<=Life,-OMPct*RO_Capex,0) -> -174493.5 | G34: =IF(AND(A34=InvYear,InvYear<Life),-InvRepl*RO_KWp,0) -> 0 | H34: =E34+F34+G34 -> 2140717.9 | I34: =I33+H34 -> 6996092 | J34: =1/(1+DiscRate)^A34 -> 0.42409762 | K34: =H34*J34 -> 907873.35 | L34: =L33+K34 -> 540781.73
A35: 10 | B35: =IF(A35<=Life,(1-Deg1)*(1-Degr)^(A35-1),0) -> 0.93780524 | C35: =RO_Gen1*B35 -> 201853.7 | D35: =Tariff*(1+TariffEsc)^(A35-1) -> 11.742959 | E35: =C35*D35 -> 2370359.7 | F35: =IF(A35<=Life,-OMPct*RO_Capex,0) -> -174493.5 | G35: =IF(AND(A35=InvYear,InvYear<Life),-InvRepl*RO_KWp,0) -> 0 | H35: =E35+F35+G35 -> 2195866.2 | I35: =I34+H35 -> 9191958.2 | J35: =1/(1+DiscRate)^A35 -> 0.38554329 | K35: =H35*J35 -> 846601.48 | L35: =L34+K35 -> 1387383.2
A36: 11 | B36: =IF(A36<=Life,(1-Deg1)*(1-Degr)^(A36-1),0) -> 0.93217841 | C36: =RO_Gen1*B36 -> 200642.58 | D36: =Tariff*(1+TariffEsc)^(A36-1) -> 12.095247 | E36: =C36*D36 -> 2426821.7 | F36: =IF(A36<=Life,-OMPct*RO_Capex,0) -> -174493.5 | G36: =IF(AND(A36=InvYear,InvYear<Life),-InvRepl*RO_KWp,0) -> 0 | H36: =E36+F36+G36 -> 2252328.2 | I36: =I35+H36 -> 11444286 | J36: =1/(1+DiscRate)^A36 -> 0.3504939 | K36: =H36*J36 -> 789427.28 | L36: =L35+K36 -> 2176810.5
A37: 12 | B37: =IF(A37<=Life,(1-Deg1)*(1-Degr)^(A37-1),0) -> 0.92658534 | C37: =RO_Gen1*B37 -> 199438.73 | D37: =Tariff*(1+TariffEsc)^(A37-1) -> 12.458105 | E37: =C37*D37 -> 2484628.6 | F37: =IF(A37<=Life,-OMPct*RO_Capex,0) -> -174493.5 | G37: =IF(AND(A37=InvYear,InvYear<Life),-InvRepl*RO_KWp,0) -> -640000 | H37: =E37+F37+G37 -> 1670135.1 | I37: =I36+H37 -> 13114421 | J37: =1/(1+DiscRate)^A37 -> 0.31863082 | K37: =H37*J37 -> 532156.5 | L37: =L36+K37 -> 2708967
... A45: 20 | B45: =IF(A45<=Life,(1-Deg1)*(1-Degr)^(A45-1),0) -> 0.88303211 | C45: =RO_Gen1*B45 -> 190064.31 | D45: =Tariff*(1+TariffEsc)^(A45-1) -> 15.781554 | E45: =C45*D45 -> 2999510.2 | F45: =IF(A45<=Life,-OMPct*RO_Capex,0) -> -174493.5 | G45: =IF(AND(A45=InvYear,InvYear<Life),-InvRepl*RO_KWp,0) -> 0 | H45: =E45+F45+G45 -> 2825016.7 | I45: =I44+H45 -> 33848874 | J45: =1/(1+DiscRate)^A45 -> 0.14864363 | K45: =H45*J45 -> 419920.73 | L45: =L44+K45 -> 7060008.7
A47: Results: campus rollout
A48: Year-1 generation (kWh) | E48: =C26 -> 213088.13
A49: Year-1 savings (₹) | E49: =E26 -> 1917793.2
A50: Year-1 O&M (₹) | E50: =-F26 -> 174493.5
A51: Simple payback (years) | E51: =IF(COUNTIF(I26:I45,"<0")>=20,"> 20",COUNTIF(I26:I45,"<0")+(-INDEX(I25:I45,COUNTIF(I26:I45,"<0")+1))/INDEX(H25:H45,COUNTIF(I26:I45,"<0")+2)) -> 5.6296845
...

Sheet Comparison
A1: How it compares on the same footprint
A2: Rollout area from 'Client'. A replaces a walkway and generates; D is the business-as-usual pair it should be compared with.
A4: Metric | B4: A. GridMats Solar Walkway | C4: B. Rooftop solar | D4: C. Solar carport | E4: D. Paver walkway + rooftop | G4: Year | H4: PVF walkway | I4: PVF rooftop
G5: 1 | H5: =(1-Deg1)*(1-Degr)^(G5-1)*(1+TariffEsc)^(G5-1)/(1+DiscRate)^G5 -> 0.9 | I5: =(1-Deg1)*(1-RoofDegr)^(G5-1)*(1+TariffEsc)^(G5-1)/(1+DiscRate)^G5 -> 0.9
A6: Footprint (m²) | B6: =CampusArea -> 1000 | C6: =CampusArea -> 1000 | D6: =CampusArea -> 1000 | E6: =CampusArea -> 1000 | G6: 2 | H6: =(1-Deg1)*(1-Degr)^(G6-1)*(1+TariffEsc)^(G6-1)/(1+DiscRate)^G6 -> 0.83767091 | I6: =(1-Deg1)*(1-RoofDegr)^(G6-1)*(1+TariffEsc)^(G6-1)/(1+DiscRate)^G6 -> 0.83935636
A7: Installed capacity (kWp) | B7: =RO_KWp -> 160 | C7: =CampusArea*RoofDens/1000 -> 190 | D7: =CampusArea*RoofDens/1000 -> 190 | E7: =CampusArea*RoofDens/1000 -> 190 | G7: 3 | H7: =(1-Deg1)*(1-Degr)^(G7-1)*(1+TariffEsc)^(G7-1)/(1+DiscRate)^G7 -> 0.77965839 | I7: =(1-Deg1)*(1-RoofDegr)^(G7-1)*(1+TariffEsc)^(G7-1)/(1+DiscRate)^G7 -> 0.78279901
A8: Total capex (₹) | B8: =RO_Capex -> 11632900 | C8: =C7*1000*RoofWp -> 7600000 | D8: =D7*1000*CarportWp -> 11590000 | E8: =CampusArea*ConvWalk+C7*1000*RoofWp -> 8800000 | G8: 4 | H8: =(1-Deg1)*(1-Degr)^(G8-1)*(1+TariffEsc)^(G8-1)/(1+DiscRate)^G8 -> 0.7256635 | I8: =(1-Deg1)*(1-RoofDegr)^(G8-1)*(1+TariffEsc)^(G8-1)/(1+DiscRate)^G8 -> 0.73005259
A9: Capex per kWp (₹) | B9: =B8/B7 -> 72705.625 | C9: =C8/C7 -> 40000 | D9: =D8/D7 -> 61000 | E9: =E8/E7 -> 46315.789 | G9: 5 | H9: =(1-Deg1)*(1-Degr)^(G9-1)*(1+TariffEsc)^(G9-1)/(1+DiscRate)^G9 -> 0.67540801 | I9: =(1-Deg1)*(1-RoofDegr)^(G9-1)*(1+TariffEsc)^(G9-1)/(1+DiscRate)^G9 -> 0.68086031
A10: Year-1 generation (kWh) | B10: =RO_Gen1 -> 215240.54 | C10: =C7*SunYear*RoofPR -> 286796.64 | D10: =D7*SunYear*RoofPR -> 286796.64 | E10: =E7*SunYear*RoofPR -> 286796.64 | G10: 6 | H10: =(1-Deg1)*(1-Degr)^(G10-1)*(1+TariffEsc)^(G10-1)/(1+DiscRate)^G10 -> 0.62863293 | I10: =(1-Deg1)*(1-RoofDegr)^(G10-1)*(1+TariffEsc)^(G10-1)/(1+DiscRate)^G10 -> 0.63498271
A11: Year-1 savings (₹) | B11: =B10*Tariff -> 1937164.8 | C11: =C10*Tariff -> 2581169.8 | D11: =D10*Tariff -> 2581169.8 | E11: =E10*Tariff -> 2581169.8 | G11: 7 | H11: =(1-Deg1)*(1-Degr)^(G11-1)*(1+TariffEsc)^(G11-1)/(1+DiscRate)^G11 -> 0.58509724 | I11: =(1-Deg1)*(1-RoofDegr)^(G11-1)*(1+TariffEsc)^(G11-1)/(1+DiscRate)^G11 -> 0.59219642
A12: Year-1 O&M (₹) | B12: =OMPct*B8 -> 174493.5 | C12: =RoofOM*C8 -> 76000 | D12: =CarportOM*D8 -> 139080 | E12: =RoofOM*C8+ConvWalkOM*CampusArea*ConvWalk -> 100000 | G12: 8 | H12: =(1-Deg1)*(1-Degr)^(G12-1)*(1+TariffEsc)^(G12-1)/(1+DiscRate)^G12 -> 0.5445766 | I12: =(1-Deg1)*(1-RoofDegr)^(G12-1)*(1+TariffEsc)^(G12-1)/(1+DiscRate)^G12 -> 0.55229315
A13: Simple payback on year-1 figures (years) | B13: =B8/(B11-B12) -> 6.5995854 | C13: =C8/(C11-C12) -> 3.0337265 | D13: =D8/(D11-D12) -> 4.7459353 | E13: =E8/(E11-E12) -> 3.5467142 | G13: 9 | H13: =(1-Deg1)*(1-Degr)^(G13-1)*(1+TariffEsc)^(G13-1)/(1+DiscRate)^G13 -> 0.5068622 | I13: =(1-Deg1)*(1-RoofDegr)^(G13-1)*(1+TariffEsc)^(G13-1)/(1+DiscRate)^G13 -> 0.51507863
A14: NPV over 20 years (₹) | B14: =-B8+B11*PVF_W-B12*ANN20 -> 6063932.4 | C14: =-C8+C11*PVF_R-C12*ANN20 -> 17686252 | D14: =-D8+D11*PVF_R-D12*ANN20 -> 13159217 | E14: =-E8+E11*PVF_R-E12*ANN20 -> 16281927 | G14: 10 | H14: =(1-Deg1)*(1-Degr)^(G14-1)*(1+TariffEsc)^(G14-1)/(1+DiscRate)^G14 -> 0.47175969 | I14: =(1-Deg1)*(1-RoofDegr)^(G14-1)*(1+TariffEsc)^(G14-1)/(1+DiscRate)^G14 -> 0.4803717
A15: Provides a walking surface | B15: Yes | C15: No | D15: Shade, not a walkway | E15: Yes | G15: 11 | H15: =(1-Deg1)*(1-Degr)^(G15-1)*(1+TariffEsc)^(G15-1)/(1+DiscRate)^G15 -> 0.43908818 | I15: =(1-Deg1)*(1-RoofDegr)^(G15-1)*(1+TariffEsc)^(G15-1)/(1+DiscRate)^G15 -> 0.44800338
A16: Needs roof or extra structure | B16: No | C16: Roof | D16: Steel canopy and footings | E16: Roof | G16: 12 | H16: =(1-Deg1)*(1-Degr)^(G16-1)*(1+TariffEsc)^(G16-1)/(1+DiscRate)^G16 -> 0.40867933 | I16: =(1-Deg1)*(1-RoofDegr)^(G16-1)*(1+TariffEsc)^(G16-1)/(1+DiscRate)^G16 -> 0.4178161
A17: Recycled plastic in the structure (t) | B17: =CampusArea*PlasticLW/1000 -> 4 | C17: 0 | D17: 0 | E17: 0 | G17: 13 | H17: =(1-Deg1)*(1-Degr)^(G17-1)*(1+TariffEsc)^(G17-1)/(1+DiscRate)^G17 -> 0.38037643 | I17: =(1-Deg1)*(1-RoofDegr)^(G17-1)*(1+TariffEsc)^(G17-1)/(1+DiscRate)^G17 -> 0.38966289
G18: 14 | H18: =(1-Deg1)*(1-Degr)^(G18-1)*(1+TariffEsc)^(G18-1)/(1+DiscRate)^G18 -> 0.35403363 | I18: =(1-Deg1)*(1-RoofDegr)^(G18-1)*(1+TariffEsc)^(G18-1)/(1+DiscRate)^G18 -> 0.36340669
A19: Rooftop and carport figures are the earlier ROI model's benchmarks. Rooftop is cheaper per kWp; the walkway earns its place where roofs are full, shaded or carry plant, and where a walkway is being built or relaid anyway (compare A with D). | G19: 15 | H19: =(1-Deg1)*(1-Degr)^(G19-1)*(1+TariffEsc)^(G19-1)/(1+DiscRate)^G19 -> 0.32951519 | I19: =(1-Deg1)*(1-RoofDegr)^(G19-1)*(1+TariffEsc)^(G19-1)/(1+DiscRate)^G19 -> 0.33891969
G20: 16 | H20: =(1-Deg1)*(1-Degr)^(G20-1)*(1+TariffEsc)^(G20-1)/(1+DiscRate)^G20 -> 0.30669477 | I20: =(1-Deg1)*(1-RoofDegr)^(G20-1)*(1+TariffEsc)^(G20-1)/(1+DiscRate)^G20 -> 0.31608267
G21: 17 | H21: =(1-Deg1)*(1-Degr)^(G21-1)*(1+TariffEsc)^(G21-1)/(1+DiscRate)^G21 -> 0.28545476 | I21: =(1-Deg1)*(1-RoofDegr)^(G21-1)*(1+TariffEsc)^(G21-1)/(1+DiscRate)^G21 -> 0.29478444
G22: 18 | H22: =(1-Deg1)*(1-Degr)^(G22-1)*(1+TariffEsc)^(G22-1)/(1+DiscRate)^G22 -> 0.26568572 | I22: =(1-Deg1)*(1-RoofDegr)^(G22-1)*(1+TariffEsc)^(G22-1)/(1+DiscRate)^G22 -> 0.27492133
G23: 19 | H23: =(1-Deg1)*(1-Degr)^(G23-1)*(1+TariffEsc)^(G23-1)/(1+DiscRate)^G23 -> 0.24728578 | I23: =(1-Deg1)*(1-RoofDegr)^(G23-1)*(1+TariffEsc)^(G23-1)/(1+DiscRate)^G23 -> 0.25639663
G24: 20 | H24: =(1-Deg1)*(1-Degr)^(G24-1)*(1+TariffEsc)^(G24-1)/(1+DiscRate)^G24 -> 0.23016011 | I24: =(1-Deg1)*(1-RoofDegr)^(G24-1)*(1+TariffEsc)^(G24-1)/(1+DiscRate)^G24 -> 0.23912016
G25: Σ | H25: =SUM(H5:H24) -> 9.9023034 | I25: =SUM(I5:I24) -> 10.047105
G26: Annuity | H26: =(1-(1+DiscRate)^-20)/DiscRate -> 8.5135637

Sheet Sensitivity
A1: Sensitivity: rollout payback (years)
A2: Simple payback on year-1 figures for the campus rollout. Each table varies two inputs and keeps the rest.
A4: Power price × performance ratio
A5: ₹ / kWh ↓ / Performance ratio → | B5: 0.6 | C5: 0.65 | D5: 0.7 | E5: 0.75 | F5: 0.8
A6: 8 | B6: =IFERROR(RO_NetM2/(PowerDens/1000*SunYear*B$5*(1-ShadeLoss)*$A6-OMPct*RO_CostM2),"n/a") -> 8.4311139 | C6: =IFERROR(RO_NetM2/(PowerDens/1000*SunYear*C$5*(1-ShadeLoss)*$A6-OMPct*RO_CostM2),"n/a") -> 7.6990539 | D6: =IFERROR(RO_NetM2/(PowerDens/1000*SunYear*D$5*(1-ShadeLoss)*$A6-OMPct*RO_CostM2),"n/a") -> 7.0839646 | E6: =IFERROR(RO_NetM2/(PowerDens/1000*SunYear*E$5*(1-ShadeLoss)*$A6-OMPct*RO_CostM2),"n/a") -> 6.5598853 | F6: =IFERROR(RO_NetM2/(PowerDens/1000*SunYear*F$5*(1-ShadeLoss)*$A6-OMPct*RO_CostM2),"n/a") -> 6.1080083
A7: 9 | B7: =IFERROR(RO_NetM2/(PowerDens/1000*SunYear*B$5*(1-ShadeLoss)*$A7-OMPct*RO_CostM2),"n/a") -> 7.378713 | C7: =IFERROR(RO_NetM2/(PowerDens/1000*SunYear*C$5*(1-ShadeLoss)*$A7-OMPct*RO_CostM2),"n/a") -> 6.7470686 | D7: =IFERROR(RO_NetM2/(PowerDens/1000*SunYear*D$5*(1-ShadeLoss)*$A7-OMPct*RO_CostM2),"n/a") -> 6.2150389 | E7: =IFERROR(RO_NetM2/(PowerDens/1000*SunYear*E$5*(1-ShadeLoss)*$A7-OMPct*RO_CostM2),"n/a") -> 5.7607813 | F7: =IFERROR(RO_NetM2/(PowerDens/1000*SunYear*F$5*(1-ShadeLoss)*$A7-OMPct*RO_CostM2),"n/a") -> 5.3684043
A8: 10 | B8: =IFERROR(RO_NetM2/(PowerDens/1000*SunYear*B$5*(1-ShadeLoss)*$A8-OMPct*RO_CostM2),"n/a") -> 6.5598853 | C8: =IFERROR(RO_NetM2/(PowerDens/1000*SunYear*C$5*(1-ShadeLoss)*$A8-OMPct*RO_CostM2),"n/a") -> 6.0046017 | D8: =IFERROR(RO_NetM2/(PowerDens/1000*SunYear*D$5*(1-ShadeLoss)*$A8-OMPct*RO_CostM2),"n/a") -> 5.5359892 | E8: =IFERROR(RO_NetM2/(PowerDens/1000*SunYear*E$5*(1-ShadeLoss)*$A8-OMPct*RO_CostM2),"n/a") -> 5.1352249 | F8: =IFERROR(RO_NetM2/(PowerDens/1000*SunYear*F$5*(1-ShadeLoss)*$A8-OMPct*RO_CostM2),"n/a") -> 4.7885682
A9: 11 | B9: =IFERROR(RO_NetM2/(PowerDens/1000*SunYear*B$5*(1-ShadeLoss)*$A9-OMPct*RO_CostM2),"n/a") -> 5.9046381 | C9: =IFERROR(RO_NetM2/(PowerDens/1000*SunYear*C$5*(1-ShadeLoss)*$A9-OMPct*RO_CostM2),"n/a") -> 5.4093421 | D9: =IFERROR(RO_NetM2/(PowerDens/1000*SunYear*D$5*(1-ShadeLoss)*$A9-OMPct*RO_CostM2),"n/a") -> 4.9907088 | E9: =IFERROR(RO_NetM2/(PowerDens/1000*SunYear*E$5*(1-ShadeLoss)*$A9-OMPct*RO_CostM2),"n/a") -> 4.6322178 | F9: =IFERROR(RO_NetM2/(PowerDens/1000*SunYear*F$5*(1-ShadeLoss)*$A9-OMPct*RO_CostM2),"n/a") -> 4.3217772
A10: 12 | B10: =IFERROR(RO_NetM2/(PowerDens/1000*SunYear*B$5*(1-ShadeLoss)*$A10-OMPct*RO_CostM2),"n/a") -> 5.3684043 | C10: =IFERROR(RO_NetM2/(PowerDens/1000*SunYear*C$5*(1-ShadeLoss)*$A10-OMPct*RO_CostM2),"n/a") -> 4.9214587 | D10: =IFERROR(RO_NetM2/(PowerDens/1000*SunYear*D$5*(1-ShadeLoss)*$A10-OMPct*RO_CostM2),"n/a") -> 4.5432141 | E10: =IFERROR(RO_NetM2/(PowerDens/1000*SunYear*E$5*(1-ShadeLoss)*$A10-OMPct*RO_CostM2),"n/a") -> 4.2189609 | F10: =IFERROR(RO_NetM2/(PowerDens/1000*SunYear*F$5*(1-ShadeLoss)*$A10-OMPct*RO_CostM2),"n/a") -> 3.9379088
A11: 13 | B11: =IFERROR(RO_NetM2/(PowerDens/1000*SunYear*B$5*(1-ShadeLoss)*$A11-OMPct*RO_CostM2),"n/a") -> 4.9214587 | C11: =IFERROR(RO_NetM2/(PowerDens/1000*SunYear*C$5*(1-ShadeLoss)*$A11-OMPct*RO_CostM2),"n/a") -> 4.5143015 | D11: =IFERROR(RO_NetM2/(PowerDens/1000*SunYear*D$5*(1-ShadeLoss)*$A11-OMPct*RO_CostM2),"n/a") -> 4.1693656 | E11: =IFERROR(RO_NetM2/(PowerDens/1000*SunYear*E$5*(1-ShadeLoss)*$A11-OMPct*RO_CostM2),"n/a") -> 3.8734008 | F11: =IFERROR(RO_NetM2/(PowerDens/1000*SunYear*F$5*(1-ShadeLoss)*$A11-OMPct*RO_CostM2),"n/a") -> 3.6166694
A12: 14 | B12: =IFERROR(RO_NetM2/(PowerDens/1000*SunYear*B$5*(1-ShadeLoss)*$A12-OMPct*RO_CostM2),"n/a") -> 4.5432141 | C12: =IFERROR(RO_NetM2/(PowerDens/1000*SunYear*C$5*(1-ShadeLoss)*$A12-OMPct*RO_CostM2),"n/a") -> 4.1693656 | D12: =IFERROR(RO_NetM2/(PowerDens/1000*SunYear*D$5*(1-ShadeLoss)*$A12-OMPct*RO_CostM2),"n/a") -> 3.8523652 | E12: =IFERROR(RO_NetM2/(PowerDens/1000*SunYear*E$5*(1-ShadeLoss)*$A12-OMPct*RO_CostM2),"n/a") -> 3.5801624 | F12: =IFERROR(RO_NetM2/(PowerDens/1000*SunYear*F$5*(1-ShadeLoss)*$A12-OMPct*RO_CostM2),"n/a") -> 3.3438879
A15: Power price × rollout PV-layer price (₹/m²)
A16: ₹ / kWh ↓ / PV layer ₹/m² → | B16: 6500 | C16: 7500 | D16: 8500 | E16: 9500
A17: 8 | B17: =IFERROR((RO_NetM2-RO_PV+B$16+LogPct*(B$16-RO_PV))/(PowerDens/1000*SunYear*PR*(1-ShadeLoss)*$A17-OMPct*(RO_CostM2-RO_PV+B$16)),"n/a") -> 5.2825772 | C17: =IFERROR((RO_NetM2-RO_PV+C$16+LogPct*(C$16-RO_PV))/(PowerDens/1000*SunYear*PR*(1-ShadeLoss)*$A17-OMPct*(RO_CostM2-RO_PV+C$16)),"n/a") -> 6.005322 | D17: =IFERROR((RO_NetM2-RO_PV+D$16+LogPct*(D$16-RO_PV))/(PowerDens/1000*SunYear*PR*(1-ShadeLoss)*$A17-OMPct*(RO_CostM2-RO_PV+D$16)),"n/a") -> 6.7420786 | E17: =IFERROR((RO_NetM2-RO_PV+E$16+LogPct*(E$16-RO_PV))/(PowerDens/1000*SunYear*PR*(1-ShadeLoss)*$A17-OMPct*(RO_CostM2-RO_PV+E$16)),"n/a") -> 7.4932584
A18: 9 | B18: =IFERROR((RO_NetM2-RO_PV+B$16+LogPct*(B$16-RO_PV))/(PowerDens/1000*SunYear*PR*(1-ShadeLoss)*$A18-OMPct*(RO_CostM2-RO_PV+B$16)),"n/a") -> 4.6483144 | C18: =IFERROR((RO_NetM2-RO_PV+C$16+LogPct*(C$16-RO_PV))/(PowerDens/1000*SunYear*PR*(1-ShadeLoss)*$A18-OMPct*(RO_CostM2-RO_PV+C$16)),"n/a") -> 5.2781973 | D18: =IFERROR((RO_NetM2-RO_PV+D$16+LogPct*(D$16-RO_PV))/(PowerDens/1000*SunYear*PR*(1-ShadeLoss)*$A18-OMPct*(RO_CostM2-RO_PV+D$16)),"n/a") -> 5.9188005 | E18: =IFERROR((RO_NetM2-RO_PV+E$16+LogPct*(E$16-RO_PV))/(PowerDens/1000*SunYear*PR*(1-ShadeLoss)*$A18-OMPct*(RO_CostM2-RO_PV+E$16)),"n/a") -> 6.5704001
A19: 10 | B19: =IFERROR((RO_NetM2-RO_PV+B$16+LogPct*(B$16-RO_PV))/(PowerDens/1000*SunYear*PR*(1-ShadeLoss)*$A19-OMPct*(RO_CostM2-RO_PV+B$16)),"n/a") -> 4.1500327 | C19: =IFERROR((RO_NetM2-RO_PV+C$16+LogPct*(C$16-RO_PV))/(PowerDens/1000*SunYear*PR*(1-ShadeLoss)*$A19-OMPct*(RO_CostM2-RO_PV+C$16)),"n/a") -> 4.7081359 | D19: =IFERROR((RO_NetM2-RO_PV+D$16+LogPct*(D$16-RO_PV))/(PowerDens/1000*SunYear*PR*(1-ShadeLoss)*$A19-OMPct*(RO_CostM2-RO_PV+D$16)),"n/a") -> 5.2747042 | E19: =IFERROR((RO_NetM2-RO_PV+E$16+LogPct*(E$16-RO_PV))/(PowerDens/1000*SunYear*PR*(1-ShadeLoss)*$A19-OMPct*(RO_CostM2-RO_PV+E$16)),"n/a") -> 5.8499315
A20: 11 | B20: =IFERROR((RO_NetM2-RO_PV+B$16+LogPct*(B$16-RO_PV))/(PowerDens/1000*SunYear*PR*(1-ShadeLoss)*$A20-OMPct*(RO_CostM2-RO_PV+B$16)),"n/a") -> 3.748236 | C20: =IFERROR((RO_NetM2-RO_PV+C$16+LogPct*(C$16-RO_PV))/(PowerDens/1000*SunYear*PR*(1-ShadeLoss)*$A20-OMPct*(RO_CostM2-RO_PV+C$16)),"n/a") -> 4.2492085 | D20: =IFERROR((RO_NetM2-RO_PV+D$16+LogPct*(D$16-RO_PV))/(PowerDens/1000*SunYear*PR*(1-ShadeLoss)*$A20-OMPct*(RO_CostM2-RO_PV+D$16)),"n/a") -> 4.7570337 | E20: =IFERROR((RO_NetM2-RO_PV+E$16+LogPct*(E$16-RO_PV))/(PowerDens/1000*SunYear*PR*(1-ShadeLoss)*$A20-OMPct*(RO_CostM2-RO_PV+E$16)),"n/a") -> 5.2718533
A21: 12 | B21: =IFERROR((RO_NetM2-RO_PV+B$16+LogPct*(B$16-RO_PV))/(PowerDens/1000*SunYear*PR*(1-ShadeLoss)*$A21-OMPct*(RO_CostM2-RO_PV+B$16)),"n/a") -> 3.4173737 | C21: =IFERROR((RO_NetM2-RO_PV+C$16+LogPct*(C$16-RO_PV))/(PowerDens/1000*SunYear*PR*(1-ShadeLoss)*$A21-OMPct*(RO_CostM2-RO_PV+C$16)),"n/a") -> 3.871803 | D21: =IFERROR((RO_NetM2-RO_PV+D$16+LogPct*(D$16-RO_PV))/(PowerDens/1000*SunYear*PR*(1-ShadeLoss)*$A21-OMPct*(RO_CostM2-RO_PV+D$16)),"n/a") -> 4.3318928 | E21: =IFERROR((RO_NetM2-RO_PV+E$16+LogPct*(E$16-RO_PV))/(PowerDens/1000*SunYear*PR*(1-ShadeLoss)*$A21-OMPct*(RO_CostM2-RO_PV+E$16)),"n/a") -> 4.7977496
A22: 13 | B22: =IFERROR((RO_NetM2-RO_PV+B$16+LogPct*(B$16-RO_PV))/(PowerDens/1000*SunYear*PR*(1-ShadeLoss)*$A22-OMPct*(RO_CostM2-RO_PV+B$16)),"n/a") -> 3.140185 | C22: =IFERROR((RO_NetM2-RO_PV+C$16+LogPct*(C$16-RO_PV))/(PowerDens/1000*SunYear*PR*(1-ShadeLoss)*$A22-OMPct*(RO_CostM2-RO_PV+C$16)),"n/a") -> 3.5559694 | D22: =IFERROR((RO_NetM2-RO_PV+D$16+LogPct*(D$16-RO_PV))/(PowerDens/1000*SunYear*PR*(1-ShadeLoss)*$A22-OMPct*(RO_CostM2-RO_PV+D$16)),"n/a") -> 3.9765082 | E22: =IFERROR((RO_NetM2-RO_PV+E$16+LogPct*(E$16-RO_PV))/(PowerDens/1000*SunYear*PR*(1-ShadeLoss)*$A22-OMPct*(RO_CostM2-RO_PV+E$16)),"n/a") -> 4.4018832
A23: 14 | B23: =IFERROR((RO_NetM2-RO_PV+B$16+LogPct*(B$16-RO_PV))/(PowerDens/1000*SunYear*PR*(1-ShadeLoss)*$A23-OMPct*(RO_CostM2-RO_PV+B$16)),"n/a") -> 2.904589 | C23: =IFERROR((RO_NetM2-RO_PV+C$16+LogPct*(C$16-RO_PV))/(PowerDens/1000*SunYear*PR*(1-ShadeLoss)*$A23-OMPct*(RO_CostM2-RO_PV+C$16)),"n/a") -> 3.2877765 | D23: =IFERROR((RO_NetM2-RO_PV+D$16+LogPct*(D$16-RO_PV))/(PowerDens/1000*SunYear*PR*(1-ShadeLoss)*$A23-OMPct*(RO_CostM2-RO_PV+D$16)),"n/a") -> 3.6750134 | E23: =IFERROR((RO_NetM2-RO_PV+E$16+LogPct*(E$16-RO_PV))/(PowerDens/1000*SunYear*PR*(1-ShadeLoss)*$A23-OMPct*(RO_CostM2-RO_PV+E$16)),"n/a") -> 4.0663641
A26: Pilot payback on the client's outlay × GridMats co-funding
A27: Co-funding of the PV layer → | B27: 0 | C27: 0.25 | D27: 0.5 | E27: 0.75
A28: Simple payback (years) | B28: =IFERROR((PilotPays+(CoFund-B27)*PVPilot*PilotArea)/(PE_Save1-PE_OM1),"n/a") -> 8.1155442 | C28: =IFERROR((PilotPays+(CoFund-C27)*PVPilot*PilotArea)/(PE_Save1-PE_OM1),"n/a") -> 6.726387 | D28: =IFERROR((PilotPays+(CoFund-D27)*PVPilot*PilotArea)/(PE_Save1-PE_OM1),"n/a") -> 5.3372298 | E28: =IFERROR((PilotPays+(CoFund-E27)*PVPilot*PilotArea)/(PE_Save1-PE_OM1),"n/a") -> 3.9480726
A30: Shading: green ≤ 6 years, amber 6-9 years, red above 9 years (applied in Excel with conditional formatting).

Sheet Scale-up
A1: Scale-up: from pilot to campus
A2: Year-1 figures. Pilot uses pilot prices; later phases use the rollout prices for their area.
A4: Measure | B4: Pilot | C4: Phase 2 | D4: Campus | E4: Portfolio | F4: Note
A5: Area (m²) | B5: =PilotArea -> 20 | C5: =Phase2Area -> 200 | D5: =CampusArea -> 1000 | E5: =PortfolioArea -> 5000
A6: Rated power (kWp) | B6: =B5*PowerDens/1000 -> 3.2 | C6: =C5*PowerDens/1000 -> 32 | D6: =D5*PowerDens/1000 -> 160 | E6: =E5*PowerDens/1000 -> 800
A7: Generation, year 1 (MWh) | B7: =B6*SpecYield/1000 -> 4.3048107 | C7: =C6*SpecYield/1000 -> 43.048107 | D7: =D6*SpecYield/1000 -> 215.24054 | E7: =E6*SpecYield/1000 -> 1076.2027
A8: Electricity saved, year 1 (₹ lakh) | B8: =B7*1000*Tariff/100000 -> 0.38743297 | C8: =C7*1000*Tariff/100000 -> 3.8743297 | D8: =D7*1000*Tariff/100000 -> 19.371648 | E8: =E7*1000*Tariff/100000 -> 96.858242
A9: CO2 avoided per year (t) | B9: =B7*GridEF -> 3.0564156 | C9: =C7*GridEF -> 30.564156 | D9: =D7*GridEF -> 152.82078 | E9: =E7*GridEF -> 764.10391
